<?xml version="1.0" encoding="UTF-8"?>
<testng-results ignored="0" total="5" passed="1" failed="4" skipped="0">
  <reporter-output>
  </reporter-output>
  <suite started-at="2024-02-24T12:26:58Z" name="Suite" finished-at="2024-02-24T12:27:01Z" duration-ms="3309">
    <groups>
    </groups>
    <test started-at="2024-02-24T12:26:58Z" name="Test" finished-at="2024-02-24T12:27:01Z" duration-ms="3309">
      <class name="apiautomation.EmployeesAPI">
        <test-method signature="Test_1_getAllEmployee()[pri:0, instance:apiautomation.EmployeesAPI@434a63ab]" started-at="2024-02-24T12:26:58Z" name="Test_1_getAllEmployee" finished-at="2024-02-24T12:27:00Z" duration-ms="1895" status="PASS">
          <reporter-output>
          </reporter-output>
        </test-method> <!-- Test_1_getAllEmployee -->
        <test-method signature="Test_2_createEmployee()[pri:0, instance:apiautomation.EmployeesAPI@434a63ab]" started-at="2024-02-24T12:27:00Z" name="Test_2_createEmployee" finished-at="2024-02-24T12:27:00Z" duration-ms="336" status="FAIL">
          <exception class="java.lang.AssertionError">
            <message>
              <![CDATA[expected:<429> but was:<200>]]>
            </message>
            <full-stacktrace>
              <![CDATA[java.lang.AssertionError: expected:<429> but was:<200>
at org.testng.AssertJUnit.fail(AssertJUnit.java:59)
at org.testng.AssertJUnit.failNotEquals(AssertJUnit.java:364)
at org.testng.AssertJUnit.assertEquals(AssertJUnit.java:80)
at org.testng.AssertJUnit.assertEquals(AssertJUnit.java:245)
at org.testng.AssertJUnit.assertEquals(AssertJUnit.java:252)
at apiautomation.EmployeesAPI.Test_2_createEmployee(EmployeesAPI.java:43)
at java.base/jdk.internal.reflect.NativeMethodAccessorImpl.invoke0(Native Method)
at java.base/jdk.internal.reflect.NativeMethodAccessorImpl.invoke(NativeMethodAccessorImpl.java:62)
at java.base/jdk.internal.reflect.DelegatingMethodAccessorImpl.invoke(DelegatingMethodAccessorImpl.java:43)
at java.base/java.lang.reflect.Method.invoke(Method.java:566)
at org.testng.internal.MethodInvocationHelper.invokeMethod(MethodInvocationHelper.java:124)
at org.testng.internal.Invoker.invokeMethod(Invoker.java:583)
at org.testng.internal.Invoker.invokeTestMethod(Invoker.java:719)
at org.testng.internal.Invoker.invokeTestMethods(Invoker.java:989)
at org.testng.internal.TestMethodWorker.invokeTestMethods(TestMethodWorker.java:125)
at org.testng.internal.TestMethodWorker.run(TestMethodWorker.java:109)
at org.testng.TestRunner.privateRun(TestRunner.java:648)
at org.testng.TestRunner.run(TestRunner.java:505)
at org.testng.SuiteRunner.runTest(SuiteRunner.java:455)
at org.testng.SuiteRunner.runSequentially(SuiteRunner.java:450)
at org.testng.SuiteRunner.privateRun(SuiteRunner.java:415)
at org.testng.SuiteRunner.run(SuiteRunner.java:364)
at org.testng.SuiteRunnerWorker.runSuite(SuiteRunnerWorker.java:52)
at org.testng.SuiteRunnerWorker.run(SuiteRunnerWorker.java:84)
at org.testng.TestNG.runSuitesSequentially(TestNG.java:1208)
at org.testng.TestNG.runSuitesLocally(TestNG.java:1137)
at org.testng.TestNG.runSuites(TestNG.java:1049)
at org.testng.TestNG.run(TestNG.java:1017)
at org.apache.maven.surefire.testng.TestNGExecutor.run(TestNGExecutor.java:284)
at org.apache.maven.surefire.testng.TestNGXmlTestSuite.execute(TestNGXmlTestSuite.java:75)
at org.apache.maven.surefire.testng.TestNGProvider.invoke(TestNGProvider.java:119)
at org.apache.maven.surefire.booter.ForkedBooter.runSuitesInProcess(ForkedBooter.java:428)
at org.apache.maven.surefire.booter.ForkedBooter.execute(ForkedBooter.java:162)
at org.apache.maven.surefire.booter.ForkedBooter.run(ForkedBooter.java:562)
at org.apache.maven.surefire.booter.ForkedBooter.main(ForkedBooter.java:548)
]]>
            </full-stacktrace>
          </exception> <!-- java.lang.AssertionError -->
          <reporter-output>
          </reporter-output>
        </test-method> <!-- Test_2_createEmployee -->
        <test-method signature="Test_3_getOneEmployee()[pri:0, instance:apiautomation.EmployeesAPI@434a63ab]" started-at="2024-02-24T12:27:00Z" name="Test_3_getOneEmployee" finished-at="2024-02-24T12:27:01Z" duration-ms="354" status="FAIL">
          <exception class="java.lang.AssertionError">
            <message>
              <![CDATA[expected:<429> but was:<200>]]>
            </message>
            <full-stacktrace>
              <![CDATA[java.lang.AssertionError: expected:<429> but was:<200>
at org.testng.AssertJUnit.fail(AssertJUnit.java:59)
at org.testng.AssertJUnit.failNotEquals(AssertJUnit.java:364)
at org.testng.AssertJUnit.assertEquals(AssertJUnit.java:80)
at org.testng.AssertJUnit.assertEquals(AssertJUnit.java:245)
at org.testng.AssertJUnit.assertEquals(AssertJUnit.java:252)
at apiautomation.EmployeesAPI.Test_3_getOneEmployee(EmployeesAPI.java:61)
at java.base/jdk.internal.reflect.NativeMethodAccessorImpl.invoke0(Native Method)
at java.base/jdk.internal.reflect.NativeMethodAccessorImpl.invoke(NativeMethodAccessorImpl.java:62)
at java.base/jdk.internal.reflect.DelegatingMethodAccessorImpl.invoke(DelegatingMethodAccessorImpl.java:43)
at java.base/java.lang.reflect.Method.invoke(Method.java:566)
at org.testng.internal.MethodInvocationHelper.invokeMethod(MethodInvocationHelper.java:124)
at org.testng.internal.Invoker.invokeMethod(Invoker.java:583)
at org.testng.internal.Invoker.invokeTestMethod(Invoker.java:719)
at org.testng.internal.Invoker.invokeTestMethods(Invoker.java:989)
at org.testng.internal.TestMethodWorker.invokeTestMethods(TestMethodWorker.java:125)
at org.testng.internal.TestMethodWorker.run(TestMethodWorker.java:109)
at org.testng.TestRunner.privateRun(TestRunner.java:648)
at org.testng.TestRunner.run(TestRunner.java:505)
at org.testng.SuiteRunner.runTest(SuiteRunner.java:455)
at org.testng.SuiteRunner.runSequentially(SuiteRunner.java:450)
at org.testng.SuiteRunner.privateRun(SuiteRunner.java:415)
at org.testng.SuiteRunner.run(SuiteRunner.java:364)
at org.testng.SuiteRunnerWorker.runSuite(SuiteRunnerWorker.java:52)
at org.testng.SuiteRunnerWorker.run(SuiteRunnerWorker.java:84)
at org.testng.TestNG.runSuitesSequentially(TestNG.java:1208)
at org.testng.TestNG.runSuitesLocally(TestNG.java:1137)
at org.testng.TestNG.runSuites(TestNG.java:1049)
at org.testng.TestNG.run(TestNG.java:1017)
at org.apache.maven.surefire.testng.TestNGExecutor.run(TestNGExecutor.java:284)
at org.apache.maven.surefire.testng.TestNGXmlTestSuite.execute(TestNGXmlTestSuite.java:75)
at org.apache.maven.surefire.testng.TestNGProvider.invoke(TestNGProvider.java:119)
at org.apache.maven.surefire.booter.ForkedBooter.runSuitesInProcess(ForkedBooter.java:428)
at org.apache.maven.surefire.booter.ForkedBooter.execute(ForkedBooter.java:162)
at org.apache.maven.surefire.booter.ForkedBooter.run(ForkedBooter.java:562)
at org.apache.maven.surefire.booter.ForkedBooter.main(ForkedBooter.java:548)
]]>
            </full-stacktrace>
          </exception> <!-- java.lang.AssertionError -->
          <reporter-output>
          </reporter-output>
        </test-method> <!-- Test_3_getOneEmployee -->
        <test-method signature="Test_4_deleteEmployee()[pri:0, instance:apiautomation.EmployeesAPI@434a63ab]" started-at="2024-02-24T12:27:01Z" name="Test_4_deleteEmployee" finished-at="2024-02-24T12:27:01Z" duration-ms="316" status="FAIL">
          <exception class="java.lang.AssertionError">
            <message>
              <![CDATA[expected:<429> but was:<200>]]>
            </message>
            <full-stacktrace>
              <![CDATA[java.lang.AssertionError: expected:<429> but was:<200>
at org.testng.AssertJUnit.fail(AssertJUnit.java:59)
at org.testng.AssertJUnit.failNotEquals(AssertJUnit.java:364)
at org.testng.AssertJUnit.assertEquals(AssertJUnit.java:80)
at org.testng.AssertJUnit.assertEquals(AssertJUnit.java:245)
at org.testng.AssertJUnit.assertEquals(AssertJUnit.java:252)
at apiautomation.EmployeesAPI.Test_4_deleteEmployee(EmployeesAPI.java:78)
at java.base/jdk.internal.reflect.NativeMethodAccessorImpl.invoke0(Native Method)
at java.base/jdk.internal.reflect.NativeMethodAccessorImpl.invoke(NativeMethodAccessorImpl.java:62)
at java.base/jdk.internal.reflect.DelegatingMethodAccessorImpl.invoke(DelegatingMethodAccessorImpl.java:43)
at java.base/java.lang.reflect.Method.invoke(Method.java:566)
at org.testng.internal.MethodInvocationHelper.invokeMethod(MethodInvocationHelper.java:124)
at org.testng.internal.Invoker.invokeMethod(Invoker.java:583)
at org.testng.internal.Invoker.invokeTestMethod(Invoker.java:719)
at org.testng.internal.Invoker.invokeTestMethods(Invoker.java:989)
at org.testng.internal.TestMethodWorker.invokeTestMethods(TestMethodWorker.java:125)
at org.testng.internal.TestMethodWorker.run(TestMethodWorker.java:109)
at org.testng.TestRunner.privateRun(TestRunner.java:648)
at org.testng.TestRunner.run(TestRunner.java:505)
at org.testng.SuiteRunner.runTest(SuiteRunner.java:455)
at org.testng.SuiteRunner.runSequentially(SuiteRunner.java:450)
at org.testng.SuiteRunner.privateRun(SuiteRunner.java:415)
at org.testng.SuiteRunner.run(SuiteRunner.java:364)
at org.testng.SuiteRunnerWorker.runSuite(SuiteRunnerWorker.java:52)
at org.testng.SuiteRunnerWorker.run(SuiteRunnerWorker.java:84)
at org.testng.TestNG.runSuitesSequentially(TestNG.java:1208)
at org.testng.TestNG.runSuitesLocally(TestNG.java:1137)
at org.testng.TestNG.runSuites(TestNG.java:1049)
at org.testng.TestNG.run(TestNG.java:1017)
at org.apache.maven.surefire.testng.TestNGExecutor.run(TestNGExecutor.java:284)
at org.apache.maven.surefire.testng.TestNGXmlTestSuite.execute(TestNGXmlTestSuite.java:75)
at org.apache.maven.surefire.testng.TestNGProvider.invoke(TestNGProvider.java:119)
at org.apache.maven.surefire.booter.ForkedBooter.runSuitesInProcess(ForkedBooter.java:428)
at org.apache.maven.surefire.booter.ForkedBooter.execute(ForkedBooter.java:162)
at org.apache.maven.surefire.booter.ForkedBooter.run(ForkedBooter.java:562)
at org.apache.maven.surefire.booter.ForkedBooter.main(ForkedBooter.java:548)
]]>
            </full-stacktrace>
          </exception> <!-- java.lang.AssertionError -->
          <reporter-output>
          </reporter-output>
        </test-method> <!-- Test_4_deleteEmployee -->
        <test-method signature="Test_5_deleteDeletedEmployee()[pri:0, instance:apiautomation.EmployeesAPI@434a63ab]" started-at="2024-02-24T12:27:01Z" name="Test_5_deleteDeletedEmployee" finished-at="2024-02-24T12:27:01Z" duration-ms="385" status="FAIL">
          <exception class="java.lang.AssertionError">
            <message>
              <![CDATA[expected:<429> but was:<200>]]>
            </message>
            <full-stacktrace>
              <![CDATA[java.lang.AssertionError: expected:<429> but was:<200>
at org.testng.AssertJUnit.fail(AssertJUnit.java:59)
at org.testng.AssertJUnit.failNotEquals(AssertJUnit.java:364)
at org.testng.AssertJUnit.assertEquals(AssertJUnit.java:80)
at org.testng.AssertJUnit.assertEquals(AssertJUnit.java:245)
at org.testng.AssertJUnit.assertEquals(AssertJUnit.java:252)
at apiautomation.EmployeesAPI.Test_5_deleteDeletedEmployee(EmployeesAPI.java:94)
at java.base/jdk.internal.reflect.NativeMethodAccessorImpl.invoke0(Native Method)
at java.base/jdk.internal.reflect.NativeMethodAccessorImpl.invoke(NativeMethodAccessorImpl.java:62)
at java.base/jdk.internal.reflect.DelegatingMethodAccessorImpl.invoke(DelegatingMethodAccessorImpl.java:43)
at java.base/java.lang.reflect.Method.invoke(Method.java:566)
at org.testng.internal.MethodInvocationHelper.invokeMethod(MethodInvocationHelper.java:124)
at org.testng.internal.Invoker.invokeMethod(Invoker.java:583)
at org.testng.internal.Invoker.invokeTestMethod(Invoker.java:719)
at org.testng.internal.Invoker.invokeTestMethods(Invoker.java:989)
at org.testng.internal.TestMethodWorker.invokeTestMethods(TestMethodWorker.java:125)
at org.testng.internal.TestMethodWorker.run(TestMethodWorker.java:109)
at org.testng.TestRunner.privateRun(TestRunner.java:648)
at org.testng.TestRunner.run(TestRunner.java:505)
at org.testng.SuiteRunner.runTest(SuiteRunner.java:455)
at org.testng.SuiteRunner.runSequentially(SuiteRunner.java:450)
at org.testng.SuiteRunner.privateRun(SuiteRunner.java:415)
at org.testng.SuiteRunner.run(SuiteRunner.java:364)
at org.testng.SuiteRunnerWorker.runSuite(SuiteRunnerWorker.java:52)
at org.testng.SuiteRunnerWorker.run(SuiteRunnerWorker.java:84)
at org.testng.TestNG.runSuitesSequentially(TestNG.java:1208)
at org.testng.TestNG.runSuitesLocally(TestNG.java:1137)
at org.testng.TestNG.runSuites(TestNG.java:1049)
at org.testng.TestNG.run(TestNG.java:1017)
at org.apache.maven.surefire.testng.TestNGExecutor.run(TestNGExecutor.java:284)
at org.apache.maven.surefire.testng.TestNGXmlTestSuite.execute(TestNGXmlTestSuite.java:75)
at org.apache.maven.surefire.testng.TestNGProvider.invoke(TestNGProvider.java:119)
at org.apache.maven.surefire.booter.ForkedBooter.runSuitesInProcess(ForkedBooter.java:428)
at org.apache.maven.surefire.booter.ForkedBooter.execute(ForkedBooter.java:162)
at org.apache.maven.surefire.booter.ForkedBooter.run(ForkedBooter.java:562)
at org.apache.maven.surefire.booter.ForkedBooter.main(ForkedBooter.java:548)
]]>
            </full-stacktrace>
          </exception> <!-- java.lang.AssertionError -->
          <reporter-output>
          </reporter-output>
        </test-method> <!-- Test_5_deleteDeletedEmployee -->
      </class> <!-- apiautomation.EmployeesAPI -->
    </test> <!-- Test -->
  </suite> <!-- Suite -->
</testng-results>
